#VRML_SIM R2021a utf8
WorldInfo {
  coordinateSystem "NUE"
}
Viewpoint {
  orientation -0.5847173230894488 0.7378858772183151 0.3370906173136044 1.3264549264854335
  position -4.576906122452148 0.5283096639561053 1.546572202933101
}
TexturedBackground {
}
TexturedBackgroundLight {
  castShadows FALSE
}
DEF curve_roads Group {
  children [
    CurvedRoadSegment {
      translation -5.98 0.001 -0.53
      rotation 0 1 0 1.01503e-06
      name "road(3)"
      width 0.28
      numberOfLanes 1
      lines []
      roadBorderWidth []
      rightBorder FALSE
      leftBorder FALSE
      curvatureRadius 0.5
      appearance DEF black_road PBRAppearance {
        baseColor 0 0 0
        metalness 0
      }
      pavementAppearance NULL
      rightBarrierBoundingObject FALSE
      leftBarrierBoundingObject FALSE
    }
    CurvedRoadSegment {
      translation -5.985 0.001555 -0.53
      rotation 0 1 0 1.01503e-06
      name "road(17)"
      width 0.14
      numberOfLanes 1
      lines []
      roadBorderWidth []
      rightBorder FALSE
      leftBorder FALSE
      curvatureRadius 0.575
      appearance DEF white_road PBRAppearance {
        metalness 0
      }
      pavementAppearance NULL
      bottomTexture [
        ""
      ]
      rightBarrierBoundingObject FALSE
      leftBarrierBoundingObject FALSE
    }
    CurvedRoadSegment {
      translation -4.88 0.001 -0.33
      rotation 0 1 0 1.5708
      name "road(1)"
      width 0.28
      numberOfLanes 1
      lines []
      roadBorderWidth []
      rightBorder FALSE
      leftBorder FALSE
      curvatureRadius 0.8
      appearance DEF black_road PBRAppearance {
        baseColor 0 0 0
        metalness 0
      }
      pavementAppearance NULL
      rightBarrierBoundingObject FALSE
      leftBarrierBoundingObject FALSE
    }
    CurvedRoadSegment {
      translation -4.88 0.001555 -0.33
      rotation 0 1 0 1.5708
      name "road(15)"
      width 0.14
      numberOfLanes 1
      lines []
      roadBorderWidth []
      rightBorder FALSE
      leftBorder FALSE
      curvatureRadius 0.87
      totalAngle 1.57
      appearance DEF white_road PBRAppearance {
        metalness 0
      }
      pavementAppearance NULL
      rightBarrierBoundingObject FALSE
      leftBarrierBoundingObject FALSE
    }
    CurvedRoadSegment {
      translation -4.88 0.001 -0.530002
      rotation 0 1 0 -3.1415853071795863
      name "road(2)"
      width 0.28
      numberOfLanes 1
      lines []
      roadBorderWidth []
      rightBorder FALSE
      leftBorder FALSE
      curvatureRadius 0.6
      appearance DEF black_road PBRAppearance {
        baseColor 0 0 0
        metalness 0
      }
      pavementAppearance NULL
      locked FALSE
      rightBarrierBoundingObject FALSE
      leftBarrierBoundingObject FALSE
    }
    CurvedRoadSegment {
      translation -4.88 0.001555 -0.530002
      rotation 0 1 0 -3.1415853071795863
      name "road(16)"
      width 0.14
      numberOfLanes 1
      lines []
      roadBorderWidth []
      rightBorder FALSE
      leftBorder FALSE
      curvatureRadius 0.53
      totalAngle 1.57
      appearance DEF white_road PBRAppearance {
        metalness 0
      }
      pavementAppearance NULL
      locked FALSE
      rightBarrierBoundingObject FALSE
      leftBarrierBoundingObject FALSE
    }
    CurvedRoadSegment {
      translation -6.96 0.001 0.570023
      rotation 0 1 0 -3.1415853071795863
      name "road(4)"
      width 0.28
      lines [
        RoadLine {
          type "continuous"
          width 0.04
        }
      ]
      roadBorderWidth []
      rightBorder FALSE
      leftBorder FALSE
      curvatureRadius 0.6
      appearance DEF black_road PBRAppearance {
        baseColor 0 0 0
        metalness 0
      }
      pavementAppearance NULL
      rightBarrierBoundingObject FALSE
      leftBarrierBoundingObject FALSE
    }
  ]
}
DEF count_walls Group {
  children [
    DEF count_wall Solid {
      translation -7.333806005630922 0.08090334087963882 1.2829361340499361
      rotation -5.422503893697624e-15 -1 -7.850662899279672e-14 1.5499270216016798
      scale 0.316783 0.316783 0.316783
      children [
        DEF count_wall Shape {
          appearance DEF count_wall PBRAppearance {
            baseColor 1 0 0
            metalness 0
          }
          geometry DEF count_wall Box {
            size 0.7 0.5 0.05
          }
        }
      ]
      name "solid(1)"
      boundingObject USE count_wall
    }
    DEF count_wall Solid {
      translation -7.32272 0.0809767 1.81285
      rotation -2.302253510505711e-16 -1 -1.0631684903217197e-15 1.5499270216016798
      scale 0.316783 0.316783 0.316783
      children [
        DEF count_wall Shape {
          appearance DEF count_wall PBRAppearance {
            baseColor 1 0 0
            metalness 0
          }
          geometry DEF count_wall Box {
            size 0.7 0.5 0.05
          }
        }
      ]
      name "solid(2)"
      boundingObject USE count_wall
    }
    DEF count_wall Solid {
      translation -7.78834 0.0809766 1.55259
      rotation -2.3261507768392925e-16 -1 -1.0988115511904062e-15 1.5499270216016798
      scale 0.316783 0.316783 0.316783
      children [
        DEF count_wall Shape {
          appearance DEF count_wall PBRAppearance {
            baseColor 1 0 0
            metalness 0
          }
          geometry DEF count_wall Box {
            size 0.7 0.5 0.05
          }
        }
      ]
      name "solid(3)"
      boundingObject USE count_wall
    }
  ]
}
DEF side_walls Group {
  children [
    Solid {
      translation -7.81983 0.0810914 2.54999
      rotation 0.7074601929208508 0 0.7067531927288284 3.1415926237874707
      scale 0.316783 0.316783 0.316783
      children [
        DEF box Shape {
          appearance PBRAppearance {
            baseColor 1 0 0
            metalness 0
          }
          geometry Box {
            size 0.75 0.6 0.05
          }
        }
      ]
      name "solid(20)"
      boundingObject USE box
    }
    Solid {
      translation -5.81194 0.0811003 2.58985
      rotation 0 1 0 1.01503e-06
      scale 0.316783 0.316783 0.316783
      children [
        DEF box Shape {
          appearance PBRAppearance {
            baseColor 1 0 0
            metalness 0
          }
          geometry Box {
            size 1.3 0.6 0.05
          }
        }
      ]
      name "solid(13)"
      boundingObject USE box
    }
    Solid {
      translation -6.09188 0.0811003 2.50749
      rotation 0 -1 0 0.785396
      scale 0.316783 0.316783 0.316783
      children [
        DEF box Shape {
          appearance PBRAppearance {
            baseColor 1 0 0
            metalness 0
          }
          geometry Box {
            size 0.75 0.6 0.05
          }
        }
      ]
      name "solid(12)"
      boundingObject USE box
    }
    Solid {
      translation -6.25451 0.0811003 2.04792
      rotation 0 -1 0 0.785396
      scale 0.316783 0.316783 0.316783
      children [
        DEF box Shape {
          appearance PBRAppearance {
            baseColor 1 0 0
            metalness 0
          }
          geometry Box {
            size 0.75 0.6 0.05
          }
        }
      ]
      name "solid(17)"
      boundingObject USE box
    }
    Solid {
      translation -6.98978 0.0811003 2.07621
      rotation 0 1 0 -2.3561953071795863
      scale 0.316783 0.316783 0.316783
      children [
        DEF box Shape {
          appearance PBRAppearance {
            baseColor 1 0 0
            metalness 0
          }
          geometry Box {
            size 1 0.6 0.05
          }
        }
      ]
      name "solid(18)"
      boundingObject USE box
    }
    Solid {
      translation -5.53194 0.0811003 2.96985
      rotation 0 1 0 1.01503e-06
      scale 0.316783 0.316783 0.316783
      children [
        DEF box Shape {
          appearance PBRAppearance {
            baseColor 1 0 0
            metalness 0
          }
          geometry Box {
            size 1.75 0.6 0.05
          }
        }
      ]
      name "solid(9)"
      boundingObject USE box
    }
    Solid {
      translation -6.61194 0.0811003 1.96985
      rotation 0 1 0 1.01503e-06
      scale 0.316783 0.316783 0.316783
      children [
        DEF box Shape {
          appearance PBRAppearance {
            baseColor 1 0 0
            metalness 0
          }
          geometry Box {
            size 1.75 0.6 0.05
          }
        }
      ]
      name "solid(16)"
      boundingObject USE box
    }
    Solid {
      translation -7.40194 0.0811003 2.66985
      rotation 0 1 0 1.01503e-06
      scale 0.316783 0.316783 0.316783
      children [
        DEF box Shape {
          appearance PBRAppearance {
            baseColor 1 0 0
            metalness 0
          }
          geometry Box {
            size 2.6 0.6 0.05
          }
        }
      ]
      name "solid(19)"
      boundingObject USE box
    }
    Solid {
      translation -6.85183 0.0811003 2.52864
      rotation 0 -1 0 -0.7854053071795866
      scale 0.316783 0.316783 0.316783
      children [
        DEF box Shape {
          appearance PBRAppearance {
            baseColor 1 0 0
            metalness 0
          }
          geometry Box {
            size 1.25 0.6 0.05
          }
        }
      ]
      name "solid(15)"
      boundingObject USE box
    }
    Solid {
      translation -4.81194 0.0811003 2.25985
      rotation 0 1 0 -1.5707953071795862
      scale 0.316783 0.316783 0.316783
      children [
        DEF box Shape {
          appearance PBRAppearance {
            baseColor 1 0 0
            metalness 0
          }
          geometry Box {
            size 1.7 0.6 0.05
          }
        }
      ]
      name "solid(10)"
      boundingObject USE box
    }
    Solid {
      translation -6.17194 0.0811003 2.27985
      rotation 0 1 0 -1.5707953071795862
      scale 0.316783 0.316783 0.316783
      children [
        DEF box Shape {
          appearance PBRAppearance {
            baseColor 1 0 0
            metalness 0
          }
          geometry Box {
            size 1 0.6 0.05
          }
        }
      ]
      name "solid(14)"
      boundingObject USE box
    }
    Solid {
      translation -5.03773 0.0811003 2.7482
      rotation 0 1 0 -2.3561953071795863
      scale 0.316783 0.316783 0.316783
      children [
        DEF box Shape {
          appearance PBRAppearance {
            baseColor 1 0 0
            metalness 0
          }
          geometry Box {
            size 2 0.6 0.05
          }
        }
      ]
      name "solid(11)"
      boundingObject USE box
    }
  ]
}
DEF track Group {
  children [
    StraightRoadSegment {
      translation -5 0.001 0.57
      rotation 0 1 0 1.01503e-06
      name "road(5)"
      width 0.28
      lines [
        RoadLine {
          type "continuous"
          width 0.04
        }
      ]
      startingRoadBorderWidth 0
      endingRoadBorderWidth 0
      rightBorder FALSE
      leftBorder FALSE
      length 0.8
      appearance USE black_road
      pavementAppearance NULL
      locked FALSE
      rightBarrierBoundingObject FALSE
      leftBarrierBoundingObject FALSE
    }
    StraightRoadSegment {
      translation -4.08 0.001 -0.34
      rotation 0 1 0 1.01503e-06
      name "road(9)"
      width 0.28
      lines [
        RoadLine {
          type "continuous"
          width 0.04
        }
      ]
      startingRoadBorderWidth 0
      endingRoadBorderWidth 0
      rightBorder FALSE
      leftBorder FALSE
      length 0.4
      appearance USE black_road
      pavementAppearance NULL
      locked FALSE
      rightBarrierBoundingObject FALSE
      leftBarrierBoundingObject FALSE
    }
    StraightRoadSegment {
      translation -4.07803 0.001 -0.0912135
      rotation 0 1 0 2.85387e-06
      name "road(19)"
      width 0.28
      numberOfLanes 1
      lines []
      startingRoadBorderWidth 0
      endingRoadBorderWidth 0
      rightBorder FALSE
      leftBorder FALSE
      length 0.2
      appearance USE black_road
      pavementAppearance NULL
      locked FALSE
      rightBarrierBoundingObject FALSE
      leftBarrierBoundingObject FALSE
    }
    StraightRoadSegment {
      translation -4.03758 0.001 0.0100002
      rotation 0 1 0 -0.785395307179586
      name "road(24)"
      width 0.28
      numberOfLanes 1
      lines []
      startingRoadBorderWidth 0
      endingRoadBorderWidth 0
      rightBorder FALSE
      leftBorder FALSE
      length 0.2
      appearance USE black_road
      pavementAppearance NULL
      locked FALSE
      rightBarrierBoundingObject FALSE
      leftBarrierBoundingObject FALSE
    }
    StraightRoadSegment {
      translation -4.2907 0.001 0.323255
      rotation 0 1 0 -1.5707953071795862
      name "road(21)"
      width 0.28
      numberOfLanes 1
      lines []
      startingRoadBorderWidth 0
      endingRoadBorderWidth 0
      rightBorder FALSE
      leftBorder FALSE
      length 0.2
      appearance USE black_road
      pavementAppearance NULL
      locked FALSE
      rightBarrierBoundingObject FALSE
      leftBarrierBoundingObject FALSE
    }
    StraightRoadSegment {
      translation -4.24968 0.001 0.222131
      rotation 0 1 0 -0.785395307179586
      name "road(22)"
      width 0.28
      numberOfLanes 1
      lines []
      startingRoadBorderWidth 0
      endingRoadBorderWidth 0
      rightBorder FALSE
      leftBorder FALSE
      length 0.2
      appearance USE black_road
      pavementAppearance NULL
      locked FALSE
      rightBarrierBoundingObject FALSE
      leftBarrierBoundingObject FALSE
    }
    StraightRoadSegment {
      translation -4.075 0.001 0.0453551
      rotation 0 1 0 -0.785395307179586
      name "road(18)"
      width 0.28
      lines [
        RoadLine {
          type "continuous"
          width 0.04
        }
      ]
      startingRoadBorderWidth 0
      endingRoadBorderWidth 0
      rightBorder FALSE
      leftBorder FALSE
      length 0.4
      appearance USE black_road
      pavementAppearance NULL
      locked FALSE
      rightBarrierBoundingObject FALSE
      leftBarrierBoundingObject FALSE
    }
    StraightRoadSegment {
      translation -4.74666 0.001 0.321125
      rotation 0 1 0 -0.785395307179586
      name "road(7)"
      width 0.28
      lines [
        RoadLine {
          type "continuous"
          width 0.04
        }
      ]
      startingRoadBorderWidth 0
      endingRoadBorderWidth 0
      rightBorder FALSE
      leftBorder FALSE
      length 0.37
      appearance USE black_road
      pavementAppearance NULL
      locked FALSE
      rightBarrierBoundingObject FALSE
      leftBarrierBoundingObject FALSE
    }
    StraightRoadSegment {
      translation -4.35141 0.001 0.325856
      rotation 0 1 0 -1.5707953071795862
      name "road(6)"
      width 0.28
      lines [
        RoadLine {
          type "continuous"
          width 0.04
        }
      ]
      startingRoadBorderWidth 0
      endingRoadBorderWidth 0
      rightBorder FALSE
      leftBorder FALSE
      length 0.4
      appearance USE black_road
      pavementAppearance NULL
      locked FALSE
      rightBarrierBoundingObject FALSE
      leftBarrierBoundingObject FALSE
    }
    StraightRoadSegment {
      translation -5.51 0.001 1.85
      rotation 0 1 0 1.5708
      name "road(14)"
      width 0.28
      numberOfLanes 1
      lines []
      startingRoadBorderWidth 0
      endingRoadBorderWidth 0
      rightBorder FALSE
      leftBorder FALSE
      length 1
      appearance USE black_road
      pavementAppearance NULL
      locked FALSE
      rightBarrierBoundingObject FALSE
      leftBarrierBoundingObject FALSE
    }
    StraightRoadSegment {
      translation -5.98 0.001 -0.029996
      rotation 0 1 0 -1.5707953071795862
      name "road(10)"
      width 0.28
      lines [
        RoadLine {
          type "continuous"
          width 0.04
        }
      ]
      rightBorder FALSE
      leftBorder FALSE
      length 1
      appearance USE black_road
      pavementAppearance NULL
      rightBarrierBoundingObject FALSE
      leftBarrierBoundingObject FALSE
    }
    StraightRoadSegment {
      translation -6.69 0.001 0.830004
      rotation 0 1 0 3.14159
      name "road(11)"
      width 0.28
      lines [
        RoadLine {
          type "continuous"
          width 0.04
        }
      ]
      rightBorder FALSE
      leftBorder FALSE
      length 1
      appearance USE black_road
      pavementAppearance NULL
      rightBarrierBoundingObject FALSE
      leftBarrierBoundingObject FALSE
    }
    StraightRoadSegment {
      translation -6.7 0.001 0.82
      rotation 0 1 0 -1.5707953071795862
      name "road(12)"
      width 0.28
      lines [
        RoadLine {
          type "continuous"
          width 0.04
        }
      ]
      rightBorder FALSE
      leftBorder FALSE
      length 1
      appearance USE black_road
      pavementAppearance NULL
      rightBarrierBoundingObject FALSE
      leftBarrierBoundingObject FALSE
    }
    StraightRoadSegment {
      translation -6.55 0.001 0.82
      rotation 0 1 0 -1.5707953071795862
      name "road(8)"
      width 0.28
      numberOfLanes 1
      lines [
        RoadLine {
          type "continuous"
          width 0.04
        }
      ]
      rightBorder FALSE
      leftBorder FALSE
      length 0.2
      appearance USE black_road
      pavementAppearance NULL
      rightBarrierBoundingObject FALSE
      leftBarrierBoundingObject FALSE
    }
    StraightRoadSegment {
      translation -7.56 0.001 2.31
      rotation 0 1 0 3.14159
      name "road(20)"
      width 0.28
      lines [
        RoadLine {
          type "continuous"
          width 0.04
        }
      ]
      rightBorder FALSE
      leftBorder FALSE
      length 1.75
      appearance USE black_road
      pavementAppearance NULL
      rightBarrierBoundingObject FALSE
      leftBarrierBoundingObject FALSE
    }
    StraightRoadSegment {
      translation -7.56 0.001 2.61
      rotation 0 1 0 3.14159
      name "road(13)"
      width 0.28
      numberOfLanes 1
      lines [
        RoadLine {
          type "continuous"
          width 0.04
        }
      ]
      rightBorder FALSE
      leftBorder FALSE
      length 0.3
      appearance USE black_road
      pavementAppearance NULL
      rightBarrierBoundingObject FALSE
      leftBarrierBoundingObject FALSE
    }
    StraightRoadSegment {
      translation -4.90012 0.001 0.476687
      rotation 0 1 0 -0.785395307179586
      name "road(23)"
      width 0.28
      numberOfLanes 1
      lines []
      startingRoadBorderWidth 0
      endingRoadBorderWidth 0
      rightBorder FALSE
      leftBorder FALSE
      length 0.2
      appearance USE black_road
      pavementAppearance NULL
      locked FALSE
      rightBarrierBoundingObject FALSE
      leftBarrierBoundingObject FALSE
    }
    StraightRoadSegment {
      translation -4.715 0.001 0.28577
      rotation 0 1 0 -0.785395307179586
      name "road(26)"
      width 0.28
      numberOfLanes 1
      lines []
      startingRoadBorderWidth 0
      endingRoadBorderWidth 0
      rightBorder FALSE
      leftBorder FALSE
      length 0.2
      appearance USE black_road
      pavementAppearance NULL
      locked FALSE
      rightBarrierBoundingObject FALSE
      leftBarrierBoundingObject FALSE
    }
    StraightRoadSegment {
      translation -4.61974 0.001 0.326273
      rotation 0 1 0 -1.5707953071795862
      name "road(27)"
      width 0.28
      numberOfLanes 1
      lines []
      startingRoadBorderWidth 0
      endingRoadBorderWidth 0
      rightBorder FALSE
      leftBorder FALSE
      length 0.2
      appearance USE black_road
      pavementAppearance NULL
      locked FALSE
      rightBarrierBoundingObject FALSE
      leftBarrierBoundingObject FALSE
    }
    StraightRoadSegment {
      translation -4.99925 0.001 0.521748
      rotation 0 1 0 2.85387e-06
      name "road(25)"
      width 0.28
      numberOfLanes 1
      lines []
      startingRoadBorderWidth 0
      endingRoadBorderWidth 0
      rightBorder FALSE
      leftBorder FALSE
      length 0.2
      appearance USE black_road
      pavementAppearance NULL
      locked FALSE
      rightBarrierBoundingObject FALSE
      leftBarrierBoundingObject FALSE
    }
    Solid {
      translation -4.99 0.002 1.51
      rotation 0 1 0 1.5708
      scale 2.05152 2.05152 2.05152
      children [
        DEF Road1 Shape {
          appearance PBRAppearance {
            baseColor 0.933333 0.933333 0.92549
            metalness 0
          }
          geometry Plane {
            size 0.15 0.5
          }
        }
      ]
      name "solid(4)"
      boundingObject USE Road1
    }
    Solid {
      translation -4.99 0.00155 1.79003
      rotation 0 1 0 1.5708
      scale 2.05152 2.05152 2.05152
      children [
        DEF Road1 Shape {
          appearance PBRAppearance {
            baseColor 0 0 0
            metalness 0
          }
          geometry Plane {
            size 0.2 0.5
          }
        }
      ]
      name "solid(6)"
      boundingObject USE Road1
    }
  ]
}
DEF flags Group {
  children [
    YoubotFlag {
      translation -4.23 0 1.68
      rotation 0 1 0 -0.261795307179586
    }
    YoubotFlag {
      translation -3.56 0 -0.3
      rotation 0 1 0 -5.307179586466759e-06
      name "youBot flag(1)"
    }
    YoubotFlag {
      translation -5.96 0 -0.44
      rotation 0 1 0 -0.785395307179586
      name "youBot flag(2)"
    }
    YoubotFlag {
      translation -8.10392 0 0.79196
      rotation 0 1 0 -0.523595307179586
      name "youBot flag(3)"
    }
    YoubotFlag {
      translation -8.12588 0 2.6
      rotation 0 1 0 -0.523595307179586
      name "youBot flag(4)"
    }
  ]
}
RectangleArena {
  translation -5.87 0 0.91
  floorSize 8 8
  floorAppearance Parquetry {
    type "light strip"
    IBLStrength 10
  }
}
Robot {
  translation -4.9953 0.0283318 1.44072
  rotation -1.8036186145338052e-06 -0.999999999996745 -1.8046969967309396e-06 -1.5700636879043643
  children [
    DEF Base Shape {
      appearance PBRAppearance {
        baseColor 0.5 0.5 0.5
        metalness 0
      }
      geometry Box {
        size 0.07 0.03 0.09
      }
    }
    DEF rear_left_wheel HingeJoint {
      jointParameters HingeJointParameters {
        position 2151.149902746123
        axis 0 0 -1
        anchor -0.05 8.15696e-08 -0.083
      }
      device [
        RotationalMotor {
          name "rear_left_motor"
        }
      ]
      endPoint Solid {
        translation -0.05 8.15696e-08 -0.083
        rotation 0.3015104845851465 -0.6742012929995321 -0.6741988165244651 2.5559107172187145
        children [
          DEF Wheel Shape {
            appearance PBRAppearance {
              baseColor 0 0 0
              roughness 1
              metalness 0
            }
            geometry Cylinder {
              height 0.016
              radius 0.027
            }
          }
        ]
        name "rear_left_wheel"
        boundingObject USE Wheel
        physics DEF Wheel Physics {
        }
        locked TRUE
      }
    }
    DEF front_left_wheel HingeJoint {
      jointParameters HingeJointParameters {
        position 2151.1498985083886
        axis 0 0 -1
        anchor 0.05 8.15696e-08 -0.083
      }
      device [
        DEF front_left_motor RotationalMotor {
          name "front_left_motor"
        }
      ]
      endPoint Solid {
        translation 0.05 8.15696e-08 -0.083
        rotation 0.30151204291656797 -0.6742009445454925 -0.6741984680717121 2.5559078602863847
        children [
          DEF Wheel Shape {
            appearance PBRAppearance {
              baseColor 0 0 0
              roughness 1
              metalness 0
            }
            geometry Cylinder {
              height 0.016
              radius 0.027
            }
          }
        ]
        name "front_left_wheel"
        boundingObject USE Wheel
        physics Physics {
        }
        locked TRUE
      }
    }
    DEF rear_right_wheel HingeJoint {
      jointParameters HingeJointParameters {
        position 2555.707702941995
        axis 0 0 -1
        anchor -0.05 8.15696e-08 0.083
      }
      device [
        DEF rear_right_motor RotationalMotor {
          name "rear_right_motor"
        }
      ]
      endPoint Solid {
        translation -0.05 8.15696e-08 0.083
        rotation -0.5858490483150387 -0.5730546680201116 -0.5730525630766545 4.201488256309906
        children [
          DEF Wheel Shape {
            appearance PBRAppearance {
              baseColor 0 0 0
              roughness 1
              metalness 0
            }
            geometry Cylinder {
              height 0.016
              radius 0.027
            }
          }
        ]
        name "rear_right_wheel"
        boundingObject USE Wheel
        physics Physics {
        }
        locked TRUE
      }
    }
    DEF front_right_wheel HingeJoint {
      jointParameters HingeJointParameters {
        position 2555.708016908807
        axis 0 0 -1
        anchor 0.05 8.15696e-08 0.083
      }
      device [
        DEF front_right_motor RotationalMotor {
          name "front_right_motor"
        }
      ]
      endPoint Solid {
        translation 0.05 8.15696e-08 0.083
        rotation -0.585969884033453 -0.5729928913069547 -0.5729907865904286 4.201668166098859
        children [
          DEF Wheel Shape {
            appearance PBRAppearance {
              baseColor 0 0 0
              roughness 1
              metalness 0
            }
            geometry Cylinder {
              height 0.016
              radius 0.027
            }
          }
        ]
        name "front_right_wheel"
        boundingObject USE Wheel
        physics Physics {
        }
        locked TRUE
      }
    }
    DEF arm Solid {
      translation 0 0 0.06
      rotation 0.5773509358560258 0.577349935856137 -0.577349935856137 -2.094395307179586
      children [
        Shape {
          appearance PBRAppearance {
            baseColor 0.341176 0.317647 0.352941
            metalness 0
          }
          geometry Box {
            size 0.03 0.03 0.14
          }
        }
      ]
      physics DEF cp Physics {
        centerOfMass [
          0 0 0
        ]
      }
    }
    DEF arm Solid {
      translation 0 0 -0.06
      rotation 0.577349935856137 0.5773509358560258 -0.577349935856137 -2.094395307179586
      children [
        Shape {
          appearance PBRAppearance {
            baseColor 0.341176 0.317647 0.352941
            metalness 0
          }
          geometry Box {
            size 0.03 0.03 0.14
          }
        }
      ]
      name "solid(1)"
      physics USE cp
    }
    DEF capsule Solid {
      translation 0 0 0.06
      rotation 0 0 -1 -1.5707953071795862
      children [
        Shape {
          appearance PBRAppearance {
            baseColor 0 0.8 1
            metalness 0
          }
          geometry Capsule {
            height 0.09
            radius 0.016
          }
        }
      ]
      name "solid(6)"
      physics DEF cp Physics {
        centerOfMass [
          0 0 0
        ]
      }
    }
    DEF capsule Solid {
      translation 0 0 -0.06
      rotation 0 0 -1 -1.5707953071795862
      children [
        Shape {
          appearance PBRAppearance {
            baseColor 0 0.8 1
            metalness 0
          }
          geometry Capsule {
            height 0.09
            radius 0.016
          }
        }
      ]
      name "solid(21)"
      physics DEF cp Physics {
        centerOfMass [
          0 0 0
        ]
      }
    }
    DEF cam_arm Solid {
      translation 0.03 0.05 0.017
      children [
        DEF pole Shape {
          appearance PBRAppearance {
            baseColor 0.3 0.3 0.3
            roughness 1
            metalness 0
          }
          geometry DEF campole Cylinder {
            height 0.069
            radius 0.0034
          }
        }
      ]
      name "cam_arm"
      boundingObject USE campole
    }
    DEF cam_box Solid {
      translation 0.03 0.09 0.017
      children [
        DEF cambox Shape {
          appearance PBRAppearance {
            baseColor 0.6 0.6 0.6
            roughness 1
            metalness 0
          }
          geometry Box {
            size 0.019 0.022 0.045
          }
        }
      ]
      name "cam_box"
      boundingObject USE cambox
    }
    DEF power_box Solid {
      translation -0.03 0.0141421 0
      rotation 0 0 1 -2.3561953071795863
      children [
        DEF powerbox Shape {
          appearance PBRAppearance {
            baseColor 0.3 0.3 0.3
            roughness 1
            metalness 0
          }
          geometry Box {
            size 0.03 0.04 0.09
          }
        }
      ]
      name "power_box"
      boundingObject USE powerbox
    }
    DEF inner_cam Solid {
      translation 0.04 0.09 0.004
      rotation 0 0 1 -1.57
      children [
        Shape {
          appearance PBRAppearance {
            baseColor 0 0 0
            roughness 1
            metalness 0
          }
          geometry Cylinder {
            height 0.002
            radius 0.005
          }
        }
      ]
      name "inner_cam"
    }
    DEF middle_layer Solid {
      translation 0.04 0.09 0.004
      rotation 0 0 1 1.57
      children [
        Shape {
          appearance PBRAppearance {
            baseColor 0.6 0.6 0.6
            roughness 1
            metalness 0
          }
          geometry Cylinder {
            height 0.0019
            radius 0.006
          }
        }
      ]
      name "middle_layer"
    }
    DEF outer_cam Solid {
      translation 0.04 0.09 0.004
      rotation 0 0 1 1.57
      children [
        Shape {
          appearance PBRAppearance {
            baseColor 0 0 0
            roughness 1
            metalness 0
          }
          geometry Cylinder {
            height 0.0018
            radius 0.007
          }
        }
      ]
      name "outer_cam"
    }
    Solid {
      translation 0.0288 0.0283 -0.03
      rotation 0 0 -1 -2.3562053071795863
      children [
        DEF pole Shape {
          appearance PBRAppearance {
            baseColor 0.3 0.3 0.3
            roughness 1
            metalness 0
          }
          geometry DEF campole Cylinder {
            height 0.06
            radius 0.0027
          }
        }
      ]
      name "solid(2)"
    }
    Solid {
      translation 0.06 0.0363 -0.03
      rotation 0 0 -1 -0.7854053071795866
      children [
        DEF pole Shape {
          appearance PBRAppearance {
            baseColor 0.3 0.3 0.3
            roughness 1
            metalness 0
          }
          geometry DEF campole Cylinder {
            height 0.04
            radius 0.0034
          }
        }
      ]
      name "solid(3)"
    }
    Solid {
      translation 0.0735 0.0094 -0.03
      rotation 0 0 -1 -5.307179586466759e-06
      children [
        DEF pole Shape {
          appearance PBRAppearance {
            baseColor 0.3 0.3 0.3
            roughness 1
            metalness 0
          }
          geometry DEF campole Cylinder {
            height 0.03
            radius 0.003
          }
        }
      ]
      name "solid(4)"
    }
    Solid {
      translation 0.0741 -0.00799998 -0.02
      rotation 0.9999999999870861 3.804949999950863e-06 -3.368999999956493e-06 -1.5707953071795862
      children [
        DEF pole Shape {
          appearance PBRAppearance {
            baseColor 0.3 0.3 0.3
            roughness 1
            metalness 0
          }
          geometry DEF campole Cylinder {
            height 0.03
            radius 0.004
          }
        }
      ]
      name "solid(7)"
    }
    Solid {
      translation 0.0741 -0.008 -6.14786e-15
      rotation 0.9999999999870861 3.804949999950863e-06 -3.368999999956493e-06 -1.5707953071795862
      children [
        DEF pole Shape {
          appearance PBRAppearance {
            baseColor 0.6 0.6 0.6
            roughness 1
            metalness 0
          }
          geometry DEF campole Cylinder {
            height 0.066
            radius 0.0024
          }
        }
      ]
      name "solid(8)"
    }
    Solid {
      translation 0.0388 -0.00169982 0.04
      rotation 0 0 -1 -1.5708053071795867
      children [
        DEF pole Shape {
          appearance PBRAppearance {
            baseColor 0.3 0.3 0.3
            roughness 1
            metalness 0
          }
          geometry DEF campole Cylinder {
            height 0.026
            radius 0.0027
          }
        }
      ]
      name "solid(9)"
    }
    Solid {
      translation 0.0507 0.017 0.04
      rotation 0 0 1 -3.1415853071795863
      children [
        DEF pole Shape {
          appearance PBRAppearance {
            baseColor 0.3 0.3 0.3
            roughness 1
            metalness 0
          }
          geometry DEF campole Cylinder {
            height 0.04
            radius 0.0027
          }
        }
      ]
      name "solid(10)"
    }
    Solid {
      translation 0.0505 0.0351 0.0545
      rotation 0.5773469358518515 0.5773519358512958 -0.5773519358512958 -2.094395307179586
      children [
        DEF pole Shape {
          appearance PBRAppearance {
            baseColor 0.3 0.3 0.3
            roughness 1
            metalness 0
          }
          geometry DEF campole Cylinder {
            height 0.034
            radius 0.0027
          }
        }
      ]
      name "solid(11)"
    }
    Solid {
      translation 0.0506998 0.0352 0.07
      rotation 3.59841e-07 5.20568e-07 -1 1.57079
      children [
        DEF pole Shape {
          appearance PBRAppearance {
            baseColor 0.3 0.3 0.3
            roughness 1
            metalness 0
          }
          geometry DEF campole Cylinder {
            height 0.04
            radius 0.0032
          }
        }
      ]
      name "solid(12)"
    }
    Solid {
      translation 0.0746 -0.00809997 0.0326
      rotation 0.7071052811837921 1.2673605039719573e-06 0.7071082811849851 3.14159
      children [
        DEF pole Shape {
          appearance PBRAppearance {
            roughness 1
            metalness 0
          }
          geometry DEF campole Cylinder {
            height 0.02
            radius 0.002
          }
        }
      ]
      name "solid(13)"
    }
    Solid {
      translation 0.0466997 0.0483003 -0.0457
      rotation 0.5773469358518515 0.5773519358512958 -0.5773519358512958 -2.094395307179586
      children [
        DEF pole Shape {
          appearance PBRAppearance {
            baseColor 0.3 0.3 0.3
            roughness 1
            metalness 0
          }
          geometry DEF campole Cylinder {
            height 0.034
            radius 0.0027
          }
        }
      ]
      name "solid(14)"
    }
    Solid {
      translation 0.0506997 0.0482 -0.06
      rotation 3.59841e-07 5.20568e-07 -1 1.57079
      children [
        DEF pole Shape {
          appearance PBRAppearance {
            baseColor 0.3 0.3 0.3
            roughness 1
            metalness 0
          }
          geometry DEF campole Cylinder {
            height 0.04
            radius 0.0032
          }
        }
      ]
      name "solid(15)"
    }
    Solid {
      translation 0.0708 0.0414 -0.06
      rotation 0 0 1 -1.5707953071795862
      children [
        Shape {
          appearance PBRAppearance {
            baseColor 0.83 0.68 0.21
            metalness 0
          }
          geometry Box {
            size 0.02 0.0002 0.018
          }
        }
      ]
      name "solid(16)"
    }
    Solid {
      translation -0.00590046 0.0319992 0.0400001
      rotation 0.9999999999935432 3.5869699999768397e-06 2.1797499999859257e-07 3.14159
      children [
        DEF pole Shape {
          appearance PBRAppearance {
            baseColor 0.6 0.6 0.6
            roughness 1
            metalness 0
          }
          geometry DEF campole Cylinder {
            height 0.066
            radius 0.0024
          }
        }
      ]
      name "solid(17)"
    }
    Solid {
      translation -0.0665 0.01 1.01962e-08
      rotation 1 0 0 -1.5707953071795862
      children [
        DEF rear_pole Shape {
          appearance PBRAppearance {
          }
          geometry Cylinder {
            height 0.1
            radius 0.002
          }
        }
      ]
      name "solid(22)"
      boundingObject USE rear_pole
    }
    Solid {
      translation -0.0665 -0.015 1.01962e-08
      rotation 1 0 0 -1.5707953071795862
      children [
        DEF rear_rod Shape {
          appearance PBRAppearance {
          }
          geometry Cylinder {
            height 0.15
            radius 0.002
          }
        }
      ]
      name "solid(23)"
      boundingObject USE rear_rod
    }
    HingeJoint {
      jointParameters HingeJointParameters {
        position 100.27007999999609
        axis 0 1 0
        anchor -0.00590046 0.06 0.0400001
      }
      endPoint Solid {
        translation -0.00590046 0.06 0.0400001
        rotation 3.661259695014413e-06 0.9999999999855056 3.947632650053537e-06 3.66610469321898
        children [
          DEF pole Shape {
            appearance PBRAppearance {
              baseColor 0.3 0.4 0.6
              roughness 1
              metalness 0
            }
            geometry DEF campole Cylinder {
              height 0.01
              radius 0.003
            }
          }
        ]
        name "solid(18)"
        boundingObject USE pole
      }
    }
    HingeJoint {
      jointParameters HingeJointParameters {
        position 1190.864640000127
        axis 0 1 0
        anchor -0.00590046 0.064 0.04
      }
      device [
        RotationalMotor {
          name "e"
        }
      ]
      endPoint Solid {
        translation -0.009722374755181899 0.064 0.04077881693338221
        rotation -0.8627397516051144 -0.4981059625257515 0.08700902882253303 3.0412070752644045
        children [
          Shape {
            appearance PBRAppearance {
              metalness 0
            }
            geometry Cone {
              bottomRadius 0.016
              height 0.005
            }
          }
        ]
        name "solid(19)"
      }
    }
    HingeJoint {
      jointParameters HingeJointParameters {
        position 1096.2752000003477
        axis 0 1 0
        anchor 0.0735 0.0094 -0.03
      }
      device [
        RotationalMotor {
          name "b"
        }
      ]
      endPoint Solid {
        translation 0.0735 0.0094 -0.03
        rotation -0.9644141089713716 0.18695716217406252 0.18695573253788422 1.6070184379870582
        children [
          DEF pole Shape {
            appearance PBRAppearance {
              roughness 1
              metalness 0
            }
            geometry DEF campole Cylinder {
              height 0.03
              radius 0.002
            }
          }
        ]
        name "solid(20)"
      }
    }
    HingeJoint {
      jointParameters HingeJointParameters {
        position 1096.2752000003477
        axis 0 1 0
        anchor 0.0735 0.0094 -0.03
      }
      device [
        RotationalMotor {
          name "c"
        }
      ]
      endPoint Solid {
        translation 0.0735 0.0094 -0.03
        rotation 0.43087422610048687 -0.6381004965747458 -0.6381027797724825 3.9552727571628417
        children [
          DEF pole Shape {
            appearance PBRAppearance {
              roughness 1
              metalness 0
            }
            geometry DEF campole Cylinder {
              height 0.03
              radius 0.002
            }
          }
        ]
        name "solid(5)"
      }
    }
    LED {
      translation -0.0427 0.0274 -0.0359
      rotation 0 0 1 2.3562
      children [
        PointLight {
          attenuation 0 0 1
          color 1 0 0
          location 0.0114 0.00039961 -2.1684e-19
          on FALSE
        }
        Shape {
          appearance PBRAppearance {
            baseColor 1 0 0
            roughness 1
            metalness 0
          }
          geometry Cylinder {
            height 0.02
            radius 0.0037
          }
        }
      ]
      name "led_1"
    }
    LED {
      translation -0.0427 0.0274 0.0359
      rotation 0 0 1 2.3562
      children [
        PointLight {
          attenuation 0 0 1
          color 0 1 0
          intensity 0.076
          location 0.0073 0.00039961 -2.1684e-19
          on FALSE
          radius 0.01
        }
        Shape {
          appearance PBRAppearance {
            baseColor 0 1 0
            roughness 1
            metalness 0
          }
          geometry Cylinder {
            height 0.02
            radius 0.0037
          }
        }
      ]
      name "led_3"
      color [
        0 1 0
      ]
    }
    LED {
      translation -0.0427 0.0274 0.0014
      rotation 0 0 1 2.3562
      children [
        PointLight {
          attenuation 0 0 1
          color 1 1 0
          intensity 0.03
          location 0.005 0.001 -2.1684e-19
          on FALSE
          radius 1
        }
        Shape {
          appearance PBRAppearance {
            baseColor 0.8 0.8 0.1
            roughness 1
            metalness 0
          }
          geometry Cylinder {
            height 0.02
            radius 0.0037
          }
        }
      ]
      name "led_2"
      color [
        1 1 0
      ]
    }
    DistanceSensor {
      translation 0.0741 -0.01 0.0024
      rotation 0 0 1 -1.5707953071795862
      children [
        Shape {
          appearance PBRAppearance {
            baseColor 0.5 0.5 0.5
            metalness 0
          }
          geometry Sphere {
            radius 0.002
          }
        }
      ]
      name "rod_center_ir"
      lookupTable [
        0 0 0
        0.04 1000 0
      ]
      type "infra-red"
    }
    DistanceSensor {
      translation 0.0741 -0.01 -0.025
      rotation 0 0 1 -1.5707953071795862
      children [
        Shape {
          appearance PBRAppearance {
            baseColor 0.5 0.5 0.5
            metalness 0
          }
          geometry Sphere {
            radius 0.002
          }
        }
      ]
      name "rod_left_ir"
      lookupTable [
        0 0 0
        0.04 1000 0
      ]
      type "infra-red"
    }
    DistanceSensor {
      translation 0.0741 -0.01 0.0267
      rotation 0 0 1 -1.5707953071795862
      children [
        Shape {
          appearance PBRAppearance {
            baseColor 0.5 0.5 0.5
            metalness 0
          }
          geometry Sphere {
            radius 0.002
          }
        }
      ]
      name "rod_right_ir"
      lookupTable [
        0 0 0
        0.04 1000 0
      ]
      type "infra-red"
    }
    DistanceSensor {
      translation 0.0706 -0.0150002 0.05
      rotation -0.5199883258809459 -0.5199863258796924 -0.677662424696596 1.95045
      children [
        Shape {
          appearance PBRAppearance {
            baseColor 0.5 0.5 0.5
            metalness 0
          }
          geometry Sphere {
            radius 0.002
          }
        }
      ]
      name "rod_ext_right_ir"
      type "infra-red"
    }
    DistanceSensor {
      translation 0.0706 -0.0150002 -0.05
      rotation 0.5199881762277486 0.5199861762270708 -0.6776626543613641 1.95045
      children [
        Shape {
          appearance PBRAppearance {
            baseColor 0.5 0.5 0.5
            metalness 0
          }
          geometry Sphere {
            radius 0.002
          }
        }
      ]
      name "rod_ext_left_ir"
      type "infra-red"
    }
    DistanceSensor {
      translation 0.068 0.0355 0.072
      rotation 0.577349935856137 0.5773509358560258 0.577349935856137 -2.094395307179586
      children [
        Shape {
          appearance PBRAppearance {
            baseColor 0.5 0.5 0.5
            metalness 0
          }
          geometry Sphere {
            radius 0.002
          }
        }
      ]
      name "ir_wall_right_up"
      lookupTable [
        0 0 0
        0.25 1000 0
      ]
      type "infra-red"
    }
    DistanceSensor {
      translation 0.068 0.048 -0.062
      rotation -0.5773509358560258 0.577349935856137 0.577349935856137 2.0944
      children [
        Shape {
          appearance PBRAppearance {
            baseColor 0.5 0.5 0.5
            metalness 0
          }
          geometry Sphere {
            radius 0.002
          }
        }
      ]
      name "ir_wall_left_up"
      lookupTable [
        0 0 0
        0.25 1000 0
      ]
      type "infra-red"
    }
    DistanceSensor {
      translation 0.0101 0.008 -0.074
      rotation 0.5773512691895147 -0.5773492691885823 -0.5773502691890485 -2.094395307179586
      children [
        Shape {
          appearance PBRAppearance {
            baseColor 0.5 0.5 0.5
            metalness 0
          }
          geometry Sphere {
            radius 0.002
          }
        }
      ]
      name "ir_wall_left_down"
      lookupTable [
        0 0 0
        0.25 1000 0
      ]
      type "infra-red"
    }
    DistanceSensor {
      translation -0.067 0.0095629 0.003
      rotation 0 0 -1 2.3554
      children [
        Shape {
          appearance PBRAppearance {
            baseColor 0.5 0.5 0.5
            metalness 0
          }
          geometry Sphere {
            radius 0.002
          }
        }
      ]
      name "st_left"
      type "infra-red"
    }
    DistanceSensor {
      translation 0.0101 0.008 0.074
      rotation 0.5773509358537164 0.5773519358536053 0.5773479358540498 -2.0943853071795866
      children [
        Shape {
          appearance PBRAppearance {
            baseColor 0.5 0.5 0.5
            metalness 0
          }
          geometry Sphere {
            radius 0.002
          }
        }
      ]
      name "ir_wall_right_down"
      lookupTable [
        0 0 0
        0.25 1000 0
      ]
      type "infra-red"
    }
    DistanceSensor {
      translation -0.065 -0.017 0.0024
      rotation 0 0 1 -2.8789953071795864
      children [
        Shape {
          appearance PBRAppearance {
            baseColor 0.5 0.5 0.5
            metalness 0
          }
          geometry Sphere {
            radius 0.002
          }
        }
      ]
      name "st_right"
      type "infra-red"
    }
    DistanceSensor {
      translation 0.0393 0.0898 0.004
      rotation -0.9999999999873015 -8.684209999889723e-07 4.964189999936962e-06 1.5708
      children [
        Shape {
          appearance PBRAppearance {
            baseColor 0 0 0
            roughness 1
            metalness 0
          }
          geometry Sphere {
            radius 0.002
          }
        }
      ]
      name "ir_cam_box"
      lookupTable [
        0 0 0
        0.3 1000 0
      ]
      type "infra-red"
    }
  ]
  name "OSART(2)"
  boundingObject USE Base
  physics Physics {
  }
  controller "finalx"
}
